Workbook

Sheet Sheet1
A1: SURNAME | B1: FIRST NAME | C1: YEAR OF BIRTH | D1: FATHER'S/MOTHER'S NAME | E1: HBM | F1: INV.# | G1: DATA IMAGE PAGE | H1: DATA FOLIO PAGE | I1: INDEX IMAGE PAGE | J1: INDEX FOLIO PAGE | K1: COMMENTS | L1: MTLINK | M1: fond | N1: zaznamid | O1: reproid
A2: ? | B2: Anna | C2: 1788 | D2: Ezechiel | E2: HBMa | F2: 2173 | G2: 19 | H2: 32 | I2: 115 | J2: 259 | L2: =IF(G2="Not available","","http://www.badatelna.eu/reprodukce/?fondId="&M2&"&zaznamId="&N2&"&reproId="&O2) -> http://www.badatelna.eu/reprodukce/?fondId=1073&zaznamId=1108959&reproId=3780012 | M2: =VLOOKUP(F2,Sheet2!$B$1:$E$19,2,FALSE) -> 1073 | N2: =VLOOKUP(F2,Sheet2!$B$1:$E$19,3,FALSE) -> 1108959 | O2: =IF(G2="Not available","",VLOOKUP(F2,Sheet2!$B$1:$E$19,4,FALSE)+(G2-1)) -> 3780012
A3: ? | B3: Fegele | C3: 1785 | D3: Jakob/Brindel | E3: HBMa | F3: 2173 | G3: 8 | H3: 10 | I3: 96 | J3: 201 | L3: =IF(G3="Not available","","http://www.badatelna.eu/reprodukce/?fondId="&M3&"&zaznamId="&N3&"&reproId="&O3) -> http://www.badatelna.eu/reprodukce/?fondId=1073&zaznamId=1108959&reproId=3780001 | M3: =VLOOKUP(F3,Sheet2!$B$1:$E$19,2,FALSE) -> 1073 | N3: =VLOOKUP(F3,Sheet2!$B$1:$E$19,3,FALSE) -> 1108959 | O3: =IF(G3="Not available","",VLOOKUP(F3,Sheet2!$B$1:$E$19,4,FALSE)+(G3-1)) -> 3780001
A4: ? | B4: Isak | C4: 1784 | D4: Mattius | E4: HBMa | F4: 2173 | G4: 5 | H4: 4 | I4: 115 | J4: 259 | L4: =IF(G4="Not available","","http://www.badatelna.eu/reprodukce/?fondId="&M4&"&zaznamId="&N4&"&reproId="&O4) -> http://www.badatelna.eu/reprodukce/?fondId=1073&zaznamId=1108959&reproId=3779998 | M4: =VLOOKUP(F4,Sheet2!$B$1:$E$19,2,FALSE) -> 1073 | N4: =VLOOKUP(F4,Sheet2!$B$1:$E$19,3,FALSE) -> 1108959 | O4: =IF(G4="Not available","",VLOOKUP(F4,Sheet2!$B$1:$E$19,4,FALSE)+(G4-1)) -> 3779998
A5: ? | B5: Katharine | C5: 1785 | D5: Lazar/Jüttel | E5: HBMa | F5: 2173 | G5: 8 | H5: 10 | I5: 91 | J5: 189 | L5: =IF(G5="Not available","","http://www.badatelna.eu/reprodukce/?fondId="&M5&"&zaznamId="&N5&"&reproId="&O5) -> http://www.badatelna.eu/reprodukce/?fondId=1073&zaznamId=1108959&reproId=3780001 | M5: =VLOOKUP(F5,Sheet2!$B$1:$E$19,2,FALSE) -> 1073 | N5: =VLOOKUP(F5,Sheet2!$B$1:$E$19,3,FALSE) -> 1108959 | O5: =IF(G5="Not available","",VLOOKUP(F5,Sheet2!$B$1:$E$19,4,FALSE)+(G5-1)) -> 3780001
A6: ? | B6: Selig | C6: 1785 | D6: Samuel | E6: HBMa | F6: 2173 | G6: 10 | H6: 15 | I6: 115 | J6: 259 | L6: =IF(G6="Not available","","http://www.badatelna.eu/reprodukce/?fondId="&M6&"&zaznamId="&N6&"&reproId="&O6) -> http://www.badatelna.eu/reprodukce/?fondId=1073&zaznamId=1108959&reproId=3780003 | M6: =VLOOKUP(F6,Sheet2!$B$1:$E$19,2,FALSE) -> 1073 | N6: =VLOOKUP(F6,Sheet2!$B$1:$E$19,3,FALSE) -> 1108959 | O6: =IF(G6="Not available","",VLOOKUP(F6,Sheet2!$B$1:$E$19,4,FALSE)+(G6-1)) -> 3780003
A7: Adel | B7: Hermina | C7: 1888 | D7: /Klara | E7: HBMa | F7: 2176 | G7: Not available | H7: 1-1 | I7: 3 | J7: Not available | L7: =IF(G7="Not available","","http://www.badatelna.eu/reprodukce/?fondId="&M7&"&zaznamId="&N7&"&reproId="&O7) | M7: =VLOOKUP(F7,Sheet2!$B$1:$E$19,2,FALSE) -> 1073 | N7: =VLOOKUP(F7,Sheet2!$B$1:$E$19,3,FALSE) -> 1108963 | O7: =IF(G7="Not available","",VLOOKUP(F7,Sheet2!$B$1:$E$19,4,FALSE)+(G7-1))
A8: Adler | B8: Abraham | C8: 1835 | D8: David | E8: HBMa | F8: 2174 | G8: 81 | H8: 20-105 | I8: 179 | J8: 179 | L8: =IF(G8="Not available","","http://www.badatelna.eu/reprodukce/?fondId="&M8&"&zaznamId="&N8&"&reproId="&O8) -> http://www.badatelna.eu/reprodukce/?fondId=1073&zaznamId=1108960&reproId=3780305 | M8: =VLOOKUP(F8,Sheet2!$B$1:$E$19,2,FALSE) -> 1073 | N8: =VLOOKUP(F8,Sheet2!$B$1:$E$19,3,FALSE) -> 1108960 | O8: =IF(G8="Not available","",VLOOKUP(F8,Sheet2!$B$1:$E$19,4,FALSE)+(G8-1)) -> 3780305
A9: Adler | B9: Anna | C9: 1873 | D9: Selig/Berta | E9: HBMa | F9: 2176 | G9: Not available | H9: 5-26 | I9: 3 | J9: Not available | L9: =IF(G9="Not available","","http://www.badatelna.eu/reprodukce/?fondId="&M9&"&zaznamId="&N9&"&reproId="&O9) | M9: =VLOOKUP(F9,Sheet2!$B$1:$E$19,2,FALSE) -> 1073 | N9: =VLOOKUP(F9,Sheet2!$B$1:$E$19,3,FALSE) -> 1108963 | O9: =IF(G9="Not available","",VLOOKUP(F9,Sheet2!$B$1:$E$19,4,FALSE)+(G9-1))
A10: Adler | B10: Barbara | C10: 1796 | D10: Isaias | E10: HBMa | F10: 2173 | G10: 34 | H10: 64 | I10: 90 | J10: 185 | L10: =IF(G10="Not available","","http://www.badatelna.eu/reprodukce/?fondId="&M10&"&zaznamId="&N10&"&reproId="&O10) -> http://www.badatelna.eu/reprodukce/?fondId=1073&zaznamId=1108959&reproId=3780027 | M10: =VLOOKUP(F10,Sheet2!$B$1:$E$19,2,FALSE) -> 1073 | N10: =VLOOKUP(F10,Sheet2!$B$1:$E$19,3,FALSE) -> 1108959 | O10: =IF(G10="Not available","",VLOOKUP(F10,Sheet2!$B$1:$E$19,4,FALSE)+(G10-1)) -> 3780027
A11: Adler | B11: Benjamin | C11: 1801 | E11: HBMa | F11: 2173 | G11: 44 | H11: 82 | I11: 90 | J11: 185 | L11: =IF(G11="Not available","","http://www.badatelna.eu/reprodukce/?fondId="&M11&"&zaznamId="&N11&"&reproId="&O11) -> http://www.badatelna.eu/reprodukce/?fondId=1073&zaznamId=1108959&reproId=3780037 | M11: =VLOOKUP(F11,Sheet2!$B$1:$E$19,2,FALSE) -> 1073 | N11: =VLOOKUP(F11,Sheet2!$B$1:$E$19,3,FALSE) -> 1108959 | O11: =IF(G11="Not available","",VLOOKUP(F11,Sheet2!$B$1:$E$19,4,FALSE)+(G11-1)) -> 3780037
A12: Adler | B12: Betti | C12: 1849 | D12: Elias | E12: HBMa | F12: 2164 | G12: 59 | H12: 57 | I12: 122 | J12: Not available | L12: =IF(G12="Not available","","http://www.badatelna.eu/reprodukce/?fondId="&M12&"&zaznamId="&N12&"&reproId="&O12) -> http://www.badatelna.eu/reprodukce/?fondId=1073&zaznamId=1108951&reproId=3778773 | M12: =VLOOKUP(F12,Sheet2!$B$1:$E$19,2,FALSE) -> 1073 | N12: =VLOOKUP(F12,Sheet2!$B$1:$E$19,3,FALSE) -> 1108951 | O12: =IF(G12="Not available","",VLOOKUP(F12,Sheet2!$B$1:$E$19,4,FALSE)+(G12-1)) -> 3778773
A13: Adler | B13: Betty | C13: 1832 | D13: David | E13: HBMa | F13: 2174 | G13: 67 | H13: 6-91 | I13: 179 | J13: 203 | K13: Schaffa | L13: =IF(G13="Not available","","http://www.badatelna.eu/reprodukce/?fondId="&M13&"&zaznamId="&N13&"&reproId="&O13) -> http://www.badatelna.eu/reprodukce/?fondId=1073&zaznamId=1108960&reproId=3780291 | M13: =VLOOKUP(F13,Sheet2!$B$1:$E$19,2,FALSE) -> 1073 | N13: =VLOOKUP(F13,Sheet2!$B$1:$E$19,3,FALSE) -> 1108960 | O13: =IF(G13="Not available","",VLOOKUP(F13,Sheet2!$B$1:$E$19,4,FALSE)+(G13-1)) -> 3780291
A14: Adler | B14: Bohdan | C14: 1872 | D14: Selig/Berta | E14: HBMa | F14: 2176 | G14: Not available | H14: 5-27 | I14: 3 | J14: Not available | L14: =IF(G14="Not available","","http://www.badatelna.eu/reprodukce/?fondId="&M14&"&zaznamId="&N14&"&reproId="&O14) | M14: =VLOOKUP(F14,Sheet2!$B$1:$E$19,2,FALSE) -> 1073 | N14: =VLOOKUP(F14,Sheet2!$B$1:$E$19,3,FALSE) -> 1108963 | O14: =IF(G14="Not available","",VLOOKUP(F14,Sheet2!$B$1:$E$19,4,FALSE)+(G14-1))
A15: Adler | B15: Chaje | C15: 1789 | D15: Isaias | E15: HBMa | F15: 2173 | G15: 21 | H15: 37 | I15: 90 | J15: 185 | L15: =IF(G15="Not available","","http://www.badatelna.eu/reprodukce/?fondId="&M15&"&zaznamId="&N15&"&reproId="&O15) -> http://www.badatelna.eu/reprodukce/?fondId=1073&zaznamId=1108959&reproId=3780014 | M15: =VLOOKUP(F15,Sheet2!$B$1:$E$19,2,FALSE) -> 1073 | N15: =VLOOKUP(F15,Sheet2!$B$1:$E$19,3,FALSE) -> 1108959 | O15: =IF(G15="Not available","",VLOOKUP(F15,Sheet2!$B$1:$E$19,4,FALSE)+(G15-1)) -> 3780014
A16: Adler | B16: David | C16: 1787 | D16: Juda | E16: HBMa | F16: 2173 | G16: 14 | H16: 22 | I16: 90 | J16: 185 | L16: =IF(G16="Not available","","http://www.badatelna.eu/reprodukce/?fondId="&M16&"&zaznamId="&N16&"&reproId="&O16) -> http://www.badatelna.eu/reprodukce/?fondId=1073&zaznamId=1108959&reproId=3780007 | M16: =VLOOKUP(F16,Sheet2!$B$1:$E$19,2,FALSE) -> 1073 | N16: =VLOOKUP(F16,Sheet2!$B$1:$E$19,3,FALSE) -> 1108959 | O16: =IF(G16="Not available","",VLOOKUP(F16,Sheet2!$B$1:$E$19,4,FALSE)+(G16-1)) -> 3780007
A17: Adler | B17: Edita | C17: 1922 | D17: Robert/Marianna | E17: HBMa | F17: 2176 | G17: Not available | H17: 1-1 | I17: 3 | J17: Not available | L17: =IF(G17="Not available","","http://www.badatelna.eu/reprodukce/?fondId="&M17&"&zaznamId="&N17&"&reproId="&O17) | M17: =VLOOKUP(F17,Sheet2!$B$1:$E$19,2,FALSE) -> 1073 | N17: =VLOOKUP(F17,Sheet2!$B$1:$E$19,3,FALSE) -> 1108963 | O17: =IF(G17="Not available","",VLOOKUP(F17,Sheet2!$B$1:$E$19,4,FALSE)+(G17-1))
A18: Adler | B18: Elenore | C18: 1851 | D18: Elias | E18: HBMa | F18: 2164 | G18: 75 | H18: 73 | I18: 122 | J18: Not available | L18: =IF(G18="Not available","","http://www.badatelna.eu/reprodukce/?fondId="&M18&"&zaznamId="&N18&"&reproId="&O18) -> http://www.badatelna.eu/reprodukce/?fondId=1073&zaznamId=1108951&reproId=3778789 | M18: =VLOOKUP(F18,Sheet2!$B$1:$E$19,2,FALSE) -> 1073 | N18: =VLOOKUP(F18,Sheet2!$B$1:$E$19,3,FALSE) -> 1108951 | O18: =IF(G18="Not available","",VLOOKUP(F18,Sheet2!$B$1:$E$19,4,FALSE)+(G18-1)) -> 3778789
A19: Adler | B19: Elsa | C19: 1899 | D19: Richard/Jana | E19: HBMa | F19: 2176 | G19: Not available | H19: 3-19 | I19: 3 | J19: Not available | L19: =IF(G19="Not available","","http://www.badatelna.eu/reprodukce/?fondId="&M19&"&zaznamId="&N19&"&reproId="&O19) | M19: =VLOOKUP(F19,Sheet2!$B$1:$E$19,2,FALSE) -> 1073 | N19: =VLOOKUP(F19,Sheet2!$B$1:$E$19,3,FALSE) -> 1108963 | O19: =IF(G19="Not available","",VLOOKUP(F19,Sheet2!$B$1:$E$19,4,FALSE)+(G19-1))
A20: Adler | B20: Elsa | C20: 1899-09-09 | D20: Richard | E20: HBMa | F20: 2165 | G20: 283 | H20: 3 | I20: 284 | J20: 258 | L20: =IF(G20="Not available","","http://www.badatelna.eu/reprodukce/?fondId="&M20&"&zaznamId="&N20&"&reproId="&O20) -> http://www.badatelna.eu/reprodukce/?fondId=1073&zaznamId=1108952&reproId=3779144 | M20: =VLOOKUP(F20,Sheet2!$B$1:$E$19,2,FALSE) -> 1073 | N20: =VLOOKUP(F20,Sheet2!$B$1:$E$19,3,FALSE) -> 1108952 | O20: =IF(G20="Not available","",VLOOKUP(F20,Sheet2!$B$1:$E$19,4,FALSE)+(G20-1)) -> 3779144
A21: Adler | B21: Emanuel | C21: 1790 | D21: Juda | E21: HBMa | F21: 2173 | G21: 23 | H21: 40 | I21: 90 | J21: 185 | L21: =IF(G21="Not available","","http://www.badatelna.eu/reprodukce/?fondId="&M21&"&zaznamId="&N21&"&reproId="&O21) -> http://www.badatelna.eu/reprodukce/?fondId=1073&zaznamId=1108959&reproId=3780016 | M21: =VLOOKUP(F21,Sheet2!$B$1:$E$19,2,FALSE) -> 1073 | N21: =VLOOKUP(F21,Sheet2!$B$1:$E$19,3,FALSE) -> 1108959 | O21: =IF(G21="Not available","",VLOOKUP(F21,Sheet2!$B$1:$E$19,4,FALSE)+(G21-1)) -> 3780016
A22: Adler | B22: Emil | C22: 1895 | D22: Julius/Matylda | E22: HBMa | F22: 2176 | G22: Not available | H22: 1-4 | I22: 3 | J22: Not available | L22: =IF(G22="Not available","","http://www.badatelna.eu/reprodukce/?fondId="&M22&"&zaznamId="&N22&"&reproId="&O22) | M22: =VLOOKUP(F22,Sheet2!$B$1:$E$19,2,FALSE) -> 1073 | N22: =VLOOKUP(F22,Sheet2!$B$1:$E$19,3,FALSE) -> 1108963 | O22: =IF(G22="Not available","",VLOOKUP(F22,Sheet2!$B$1:$E$19,4,FALSE)+(G22-1))
A23: Adler | B23: Emil | C23: 1895-02-21 | D23: Julius | E23: HBMa | F23: 2165 | G23: 254 | H23: 1 | I23: 252 | J23: 228 | L23: =IF(G23="Not available","","http://www.badatelna.eu/reprodukce/?fondId="&M23&"&zaznamId="&N23&"&reproId="&O23) -> http://www.badatelna.eu/reprodukce/?fondId=1073&zaznamId=1108952&reproId=3779115 | M23: =VLOOKUP(F23,Sheet2!$B$1:$E$19,2,FALSE) -> 1073 | N23: =VLOOKUP(F23,Sheet2!$B$1:$E$19,3,FALSE) -> 1108952 | O23: =IF(G23="Not available","",VLOOKUP(F23,Sheet2!$B$1:$E$19,4,FALSE)+(G23-1)) -> 3779115
A24: Adler | B24: Enoch | C24: 1799 | D24: Juda | E24: HBMa | F24: 2173 | G24: 40 | H24: 74 | I24: 90 | J24: 185 | L24: =IF(G24="Not available","","http://www.badatelna.eu/reprodukce/?fondId="&M24&"&zaznamId="&N24&"&reproId="&O24) -> http://www.badatelna.eu/reprodukce/?fondId=1073&zaznamId=1108959&reproId=3780033 | M24: =VLOOKUP(F24,Sheet2!$B$1:$E$19,2,FALSE) -> 1073 | N24: =VLOOKUP(F24,Sheet2!$B$1:$E$19,3,FALSE) -> 1108959 | O24: =IF(G24="Not available","",VLOOKUP(F24,Sheet2!$B$1:$E$19,4,FALSE)+(G24-1)) -> 3780033
A25: Adler | B25: Friederike | C25: 1867-12-14 | D25: Seligmann | E25: HBMa | F25: 2165 | G25: 27 | H25: 24 | I25: 80 | J25: Not available | L25: =IF(G25="Not available","","http://www.badatelna.eu/reprodukce/?fondId="&M25&"&zaznamId="&N25&"&reproId="&O25) -> http://www.badatelna.eu/reprodukce/?fondId=1073&zaznamId=1108952&reproId=3778888 | M25: =VLOOKUP(F25,Sheet2!$B$1:$E$19,2,FALSE) -> 1073 | N25: =VLOOKUP(F25,Sheet2!$B$1:$E$19,3,FALSE) -> 1108952 | O25: =IF(G25="Not available","",VLOOKUP(F25,Sheet2!$B$1:$E$19,4,FALSE)+(G25-1)) -> 3778888
A26: Adler | B26: Hersh | C26: 1794 | D26: Isaias | E26: HBMa | F26: 2173 | G26: 31 | H26: 57 | I26: 90 | J26: 185 | L26: =IF(G26="Not available","","http://www.badatelna.eu/reprodukce/?fondId="&M26&"&zaznamId="&N26&"&reproId="&O26) -> http://www.badatelna.eu/reprodukce/?fondId=1073&zaznamId=1108959&reproId=3780024 | M26: =VLOOKUP(F26,Sheet2!$B$1:$E$19,2,FALSE) -> 1073 | N26: =VLOOKUP(F26,Sheet2!$B$1:$E$19,3,FALSE) -> 1108959 | O26: =IF(G26="Not available","",VLOOKUP(F26,Sheet2!$B$1:$E$19,4,FALSE)+(G26-1)) -> 3780024
A27: Adler | B27: Jakob | C27: 1794 | D27: Juda | E27: HBMa | F27: 2173 | G27: 31 | H27: 57 | I27: 90 | J27: 185 | L27: =IF(G27="Not available","","http://www.badatelna.eu/reprodukce/?fondId="&M27&"&zaznamId="&N27&"&reproId="&O27) -> http://www.badatelna.eu/reprodukce/?fondId=1073&zaznamId=1108959&reproId=3780024 | M27: =VLOOKUP(F27,Sheet2!$B$1:$E$19,2,FALSE) -> 1073 | N27: =VLOOKUP(F27,Sheet2!$B$1:$E$19,3,FALSE) -> 1108959 | O27: =IF(G27="Not available","",VLOOKUP(F27,Sheet2!$B$1:$E$19,4,FALSE)+(G27-1)) -> 3780024
A28: Adler | B28: Jakob | C28: 1836 | D28: David | E28: HBMa | F28: 2174 | G28: 89 | H28: 28-113 | I28: 179 | J28: 179 | L28: =IF(G28="Not available","","http://www.badatelna.eu/reprodukce/?fondId="&M28&"&zaznamId="&N28&"&reproId="&O28) -> http://www.badatelna.eu/reprodukce/?fondId=1073&zaznamId=1108960&reproId=3780313 | M28: =VLOOKUP(F28,Sheet2!$B$1:$E$19,2,FALSE) -> 1073 | N28: =VLOOKUP(F28,Sheet2!$B$1:$E$19,3,FALSE) -> 1108960 | O28: =IF(G28="Not available","",VLOOKUP(F28,Sheet2!$B$1:$E$19,4,FALSE)+(G28-1)) -> 3780313
A29: Adler | B29: Joachim | C29: 1834 | D29: David | E29: HBMa | F29: 2174 | G29: 75 | H29: 14-99 | I29: 179 | J29: 179 | L29: =IF(G29="Not available","","http://www.badatelna.eu/reprodukce/?fondId="&M29&"&zaznamId="&N29&"&reproId="&O29) -> http://www.badatelna.eu/reprodukce/?fondId=1073&zaznamId=1108960&reproId=3780299 | M29: =VLOOKUP(F29,Sheet2!$B$1:$E$19,2,FALSE) -> 1073 | N29: =VLOOKUP(F29,Sheet2!$B$1:$E$19,3,FALSE) -> 1108960 | O29: =IF(G29="Not available","",VLOOKUP(F29,Sheet2!$B$1:$E$19,4,FALSE)+(G29-1)) -> 3780299
A30: Adler | B30: Joseph | C30: 1827 | E30: HBMa | F30: 2173 | G30: 82 | H30: 156 | I30: 90 | J30: 185 | L30: =IF(G30="Not available","","http://www.badatelna.eu/reprodukce/?fondId="&M30&"&zaznamId="&N30&"&reproId="&O30) -> http://www.badatelna.eu/reprodukce/?fondId=1073&zaznamId=1108959&reproId=3780075 | M30: =VLOOKUP(F30,Sheet2!$B$1:$E$19,2,FALSE) -> 1073 | N30: =VLOOKUP(F30,Sheet2!$B$1:$E$19,3,FALSE) -> 1108959 | O30: =IF(G30="Not available","",VLOOKUP(F30,Sheet2!$B$1:$E$19,4,FALSE)+(G30-1)) -> 3780075
A31: Adler | B31: Judith | C31: 1838 | D31: David | E31: HBMa | F31: 2174 | G31: 102 | H31: 41-125 | I31: 179 | J31: 179 | L31: =IF(G31="Not available","","http://www.badatelna.eu/reprodukce/?fondId="&M31&"&zaznamId="&N31&"&reproId="&O31) -> http://www.badatelna.eu/reprodukce/?fondId=1073&zaznamId=1108960&reproId=3780326 | M31: =VLOOKUP(F31,Sheet2!$B$1:$E$19,2,FALSE) -> 1073 | N31: =VLOOKUP(F31,Sheet2!$B$1:$E$19,3,FALSE) -> 1108960 | O31: =IF(G31="Not available","",VLOOKUP(F31,Sheet2!$B$1:$E$19,4,FALSE)+(G31-1)) -> 3780326
A32: Adler | B32: Julius | C32: 1843 | D32: David | E32: HBMa | F32: 2174 | G32: 139 | H32: 78-161 | I32: 179 | J32: 179 | L32: =IF(G32="Not available","","http://www.badatelna.eu/reprodukce/?fondId="&M32&"&zaznamId="&N32&"&reproId="&O32) -> http://www.badatelna.eu/reprodukce/?fondId=1073&zaznamId=1108960&reproId=3780363 | M32: =VLOOKUP(F32,Sheet2!$B$1:$E$19,2,FALSE) -> 1073 | N32: =VLOOKUP(F32,Sheet2!$B$1:$E$19,3,FALSE) -> 1108960 | O32: =IF(G32="Not available","",VLOOKUP(F32,Sheet2!$B$1:$E$19,4,FALSE)+(G32-1)) -> 3780363
A33: Adler | B33: Julius | C33: 1864 | E33: HBM | F33: 999 | G33: 50 | H33: 48 | I33: 62 | J33: 95 | L33: =IF(G33="Not available","","http://www.badatelna.eu/reprodukce/?fondId="&M33&"&zaznamId="&N33&"&reproId="&O33) -> http://www.badatelna.eu/reprodukce/?fondId=241&zaznamId=1133739&reproId=3885779 | M33: =VLOOKUP(F33,Sheet2!$B$1:$E$19,2,FALSE) -> 241 | N33: =VLOOKUP(F33,Sheet2!$B$1:$E$19,3,FALSE) -> 1133739 | O33: =IF(G33="Not available","",VLOOKUP(F33,Sheet2!$B$1:$E$19,4,FALSE)+(G33-1)) -> 3885779
A34: Adler | B34: Lea | C34: 1824 | E34: HBMa | F34: 2173 | G34: 75 | H34: 143 | I34: 90 | J34: 185 | L34: =IF(G34="Not available","","http://www.badatelna.eu/reprodukce/?fondId="&M34&"&zaznamId="&N34&"&reproId="&O34) -> http://www.badatelna.eu/reprodukce/?fondId=1073&zaznamId=1108959&reproId=3780068 | M34: =VLOOKUP(F34,Sheet2!$B$1:$E$19,2,FALSE) -> 1073 | N34: =VLOOKUP(F34,Sheet2!$B$1:$E$19,3,FALSE) -> 1108959 | O34: =IF(G34="Not available","",VLOOKUP(F34,Sheet2!$B$1:$E$19,4,FALSE)+(G34-1)) -> 3780068
A35: Adler | B35: Marie | C35: 1827 | E35: HBMa | F35: 2173 | G35: 78 | H35: 150 | I35: 90 | J35: 185 | L35: =IF(G35="Not available","","http://www.badatelna.eu/reprodukce/?fondId="&M35&"&zaznamId="&N35&"&reproId="&O35) -> http://www.badatelna.eu/reprodukce/?fondId=1073&zaznamId=1108959&reproId=3780071 | M35: =VLOOKUP(F35,Sheet2!$B$1:$E$19,2,FALSE) -> 1073 | N35: =VLOOKUP(F35,Sheet2!$B$1:$E$19,3,FALSE) -> 1108959 | O35: =IF(G35="Not available","",VLOOKUP(F35,Sheet2!$B$1:$E$19,4,FALSE)+(G35-1)) -> 3780071
A36: Adler | B36: Marta | C36: 1921 | D36: Simon/Marie | E36: HBMa | F36: 2176 | G36: Not available | H36: 1-4 | I36: 3 | J36: Not available | L36: =IF(G36="Not available","","http://www.badatelna.eu/reprodukce/?fondId="&M36&"&zaznamId="&N36&"&reproId="&O36) | M36: =VLOOKUP(F36,Sheet2!$B$1:$E$19,2,FALSE) -> 1073 | N36: =VLOOKUP(F36,Sheet2!$B$1:$E$19,3,FALSE) -> 1108963 | O36: =IF(G36="Not available","",VLOOKUP(F36,Sheet2!$B$1:$E$19,4,FALSE)+(G36-1))
A37: Adler | B37: Moric (Moriz) | C37: 1870 | D37: Selig/Berta | E37: HBMa | F37: 2176 | G37: Not available | H37: 5-25 | I37: 3 | J37: Not available | L37: =IF(G37="Not available","","http://www.badatelna.eu/reprodukce/?fondId="&M37&"&zaznamId="&N37&"&reproId="&O37) | M37: =VLOOKUP(F37,Sheet2!$B$1:$E$19,2,FALSE) -> 1073 | N37: =VLOOKUP(F37,Sheet2!$B$1:$E$19,3,FALSE) -> 1108963 | O37: =IF(G37="Not available","",VLOOKUP(F37,Sheet2!$B$1:$E$19,4,FALSE)+(G37-1))
A38: Adler | B38: Moyses | C38: 1796 | D38: Juda | E38: HBMa | F38: 2173 | G38: 34 | H38: 64 | I38: 90 | J38: 185 | L38: =IF(G38="Not available","","http://www.badatelna.eu/reprodukce/?fondId="&M38&"&zaznamId="&N38&"&reproId="&O38) -> http://www.badatelna.eu/reprodukce/?fondId=1073&zaznamId=1108959&reproId=3780027 | M38: =VLOOKUP(F38,Sheet2!$B$1:$E$19,2,FALSE) -> 1073 | N38: =VLOOKUP(F38,Sheet2!$B$1:$E$19,3,FALSE) -> 1108959 | O38: =IF(G38="Not available","",VLOOKUP(F38,Sheet2!$B$1:$E$19,4,FALSE)+(G38-1)) -> 3780027
A39: Adler | B39: Moyses | C39: 1805 | D39: Isaias | E39: HBMa | F39: 2173 | G39: 50 | H39: 94 | I39: 90 | J39: 185 | L39: =IF(G39="Not available","","http://www.badatelna.eu/reprodukce/?fondId="&M39&"&zaznamId="&N39&"&reproId="&O39) -> http://www.badatelna.eu/reprodukce/?fondId=1073&zaznamId=1108959&reproId=3780043 | M39: =VLOOKUP(F39,Sheet2!$B$1:$E$19,2,FALSE) -> 1073 | N39: =VLOOKUP(F39,Sheet2!$B$1:$E$19,3,FALSE) -> 1108959 | O39: =IF(G39="Not available","",VLOOKUP(F39,Sheet2!$B$1:$E$19,4,FALSE)+(G39-1)) -> 3780043
A40: Adler | B40: Rachel | C40: 1808 | E40: HBMa | F40: 2173 | G40: 54 | H40: 102 | I40: 90 | J40: 185 | L40: =IF(G40="Not available","","http://www.badatelna.eu/reprodukce/?fondId="&M40&"&zaznamId="&N40&"&reproId="&O40) -> http://www.badatelna.eu/reprodukce/?fondId=1073&zaznamId=1108959&reproId=3780047 | M40: =VLOOKUP(F40,Sheet2!$B$1:$E$19,2,FALSE) -> 1073 | N40: =VLOOKUP(F40,Sheet2!$B$1:$E$19,3,FALSE) -> 1108959 | O40: =IF(G40="Not available","",VLOOKUP(F40,Sheet2!$B$1:$E$19,4,FALSE)+(G40-1)) -> 3780047
...

Sheet Sheet2
B1: inv | C1: fond | D1: zaznamid | E1: reproid | F1: page
A2: http://www.badatelna.eu/reprodukce/?fondId=1073&zaznamId=1108960&reproId=3780225 | B2: 995 | C2: 241 | D2: 1133735 | E2: 3885429 | F2: 1
B3: 996 | C3: 241 | D3: 1133736 | E3: 3885569 | F3: 1
B4: 997 | C4: 241 | D4: 1133737 | E4: 3885619 | F4: 1
B5: 998 | C5: 241 | D5: 1133738 | E5: 3885647 | F5: 1
B6: 999 | C6: 241 | D6: 1133739 | E6: 3885730 | F6: 1
B7: 2164 | C7: 1073 | D7: 1108951 | E7: 3778715 | F7: 1
B8: 2165 | C8: 1073 | D8: 1108952 | E8: 3778862 | F8: 1
B9: 2166 | C9: 1073 | D9: 1108953 | E9: 3779225 | F9: 1
B10: 2167 | C10: 1073 | D10: 1108954 | E10: 3779284 | F10: 1
B11: 2168 | C11: 1073 | D11: 1108955 | E11: 3779305 | F11: 1
B12: 2169 | C12: 1073 | D12: 1110078 | E12: 3830578 | F12: 1
B13: 2170 | C13: 1073 | D13: 1108956 | E13: 3779593 | F13: 1
B14: 2171 | C14: 1073 | D14: 1108957 | E14: 3779668 | F14: 1
... B19: 2176 | C19: 1073 | D19: 1108963 | E19: 3780562 | F19: 1
