Workbook

Sheet Sheet1
A1: SURNAME | B1: FIRST NAME | C1: DATE OF DEATH (D-M-Y) | D1: HBM(a) | E1: INV. | F1: DATA IMAGE PAGE | G1: DATA FOLIO PAGE | H1: INDEX IMAGE PAGE | I1: INDEX FOLIO PAGE | J1: MTLINK | K1: fond | L1: zaznamid | M1: reproid
A2: ? | B2: Hershmann | C2: 15-1-1790 | D2: HBMa | E2: 2173 | F2: 196 | G2: 2 | H2: Not available | I2: Not available | J2: =IF(LEN(TRIM(E2))=0,"","http://www.badatelna.eu/reprodukce/?fondId="&K2&"&zaznamId="&L2&"&reproId="&M2) -> http://www.badatelna.eu/reprodukce/?fondId=1073&zaznamId=1108959&reproId=3780189 | K2: =IF(LEN(TRIM(E2))=0,"",VLOOKUP(E2,Sheet2!$B$1:$E$19,2,FALSE)) -> 1073 | L2: =IF(LEN(TRIM(E2))=0,"",VLOOKUP(E2,Sheet2!$B$1:$E$19,3,FALSE)) -> 1108959 | M2: =IF(LEN(TRIM(E2))=0,"",VLOOKUP(E2,Sheet2!$B$1:$E$19,4,FALSE))+(F2-1) -> 3780189
A3: ? | B3: Juda | C3: 23-8-1830 | D3: HBMa | E3: 2173 | F3: 212 | G3: 34 | H3: Not available | I3: Not available | J3: =IF(LEN(TRIM(E3))=0,"","http://www.badatelna.eu/reprodukce/?fondId="&K3&"&zaznamId="&L3&"&reproId="&M3) -> http://www.badatelna.eu/reprodukce/?fondId=1073&zaznamId=1108959&reproId=3780205 | K3: =IF(LEN(TRIM(E3))=0,"",VLOOKUP(E3,Sheet2!$B$1:$E$19,2,FALSE)) -> 1073 | L3: =IF(LEN(TRIM(E3))=0,"",VLOOKUP(E3,Sheet2!$B$1:$E$19,3,FALSE)) -> 1108959 | M3: =IF(LEN(TRIM(E3))=0,"",VLOOKUP(E3,Sheet2!$B$1:$E$19,4,FALSE))+(F3-1) -> 3780205
A4: Abeles | B4: Willhelm | C4: 5155 | D4: HBMa | E4: 2172 | F4: 184 | G4: 175 | H4: Not available | I4: Not available | J4: =IF(LEN(TRIM(E4))=0,"","http://www.badatelna.eu/reprodukce/?fondId="&K4&"&zaznamId="&L4&"&reproId="&M4) -> http://www.badatelna.eu/reprodukce/?fondId=1073&zaznamId=1108958&reproId=3779925 | K4: =IF(LEN(TRIM(E4))=0,"",VLOOKUP(E4,Sheet2!$B$1:$E$19,2,FALSE)) -> 1073 | L4: =IF(LEN(TRIM(E4))=0,"",VLOOKUP(E4,Sheet2!$B$1:$E$19,3,FALSE)) -> 1108958 | M4: =IF(LEN(TRIM(E4))=0,"",VLOOKUP(E4,Sheet2!$B$1:$E$19,4,FALSE))+(F4-1) -> 3779925
A5: Adel | B5: Hermine | C5: 17-1-1888 | D5: HBMa | E5: 2172 | F5: 64 | G5: 63 | H5: Not available | I5: Not available | J5: =IF(LEN(TRIM(E5))=0,"","http://www.badatelna.eu/reprodukce/?fondId="&K5&"&zaznamId="&L5&"&reproId="&M5) -> http://www.badatelna.eu/reprodukce/?fondId=1073&zaznamId=1108958&reproId=3779805 | K5: =IF(LEN(TRIM(E5))=0,"",VLOOKUP(E5,Sheet2!$B$1:$E$19,2,FALSE)) -> 1073 | L5: =IF(LEN(TRIM(E5))=0,"",VLOOKUP(E5,Sheet2!$B$1:$E$19,3,FALSE)) -> 1108958 | M5: =IF(LEN(TRIM(E5))=0,"",VLOOKUP(E5,Sheet2!$B$1:$E$19,4,FALSE))+(F5-1) -> 3779805
A6: Adler | B6: Anna | C6: 12-7-1880 | D6: HBMa | E6: 2172 | F6: 18 | G6: 17 | H6: Not available | I6: Not available | J6: =IF(LEN(TRIM(E6))=0,"","http://www.badatelna.eu/reprodukce/?fondId="&K6&"&zaznamId="&L6&"&reproId="&M6) -> http://www.badatelna.eu/reprodukce/?fondId=1073&zaznamId=1108958&reproId=3779759 | K6: =IF(LEN(TRIM(E6))=0,"",VLOOKUP(E6,Sheet2!$B$1:$E$19,2,FALSE)) -> 1073 | L6: =IF(LEN(TRIM(E6))=0,"",VLOOKUP(E6,Sheet2!$B$1:$E$19,3,FALSE)) -> 1108958 | M6: =IF(LEN(TRIM(E6))=0,"",VLOOKUP(E6,Sheet2!$B$1:$E$19,4,FALSE))+(F6-1) -> 3779759
A7: Adler | B7: Barbara | C7: 9-1-1881 | D7: HBMa | E7: 2172 | F7: 19 | G7: 18 | H7: 24 | I7: 23 | J7: =IF(LEN(TRIM(E7))=0,"","http://www.badatelna.eu/reprodukce/?fondId="&K7&"&zaznamId="&L7&"&reproId="&M7) -> http://www.badatelna.eu/reprodukce/?fondId=1073&zaznamId=1108958&reproId=3779760 | K7: =IF(LEN(TRIM(E7))=0,"",VLOOKUP(E7,Sheet2!$B$1:$E$19,2,FALSE)) -> 1073 | L7: =IF(LEN(TRIM(E7))=0,"",VLOOKUP(E7,Sheet2!$B$1:$E$19,3,FALSE)) -> 1108958 | M7: =IF(LEN(TRIM(E7))=0,"",VLOOKUP(E7,Sheet2!$B$1:$E$19,4,FALSE))+(F7-1) -> 3779760
A8: Adler | B8: Charlotte | C8: 4-7-1878 | D8: HBMa | E8: 2172 | F8: 6 | G8: 3 | H8: 8 | I8: 1 | J8: =IF(LEN(TRIM(E8))=0,"","http://www.badatelna.eu/reprodukce/?fondId="&K8&"&zaznamId="&L8&"&reproId="&M8) -> http://www.badatelna.eu/reprodukce/?fondId=1073&zaznamId=1108958&reproId=3779747 | K8: =IF(LEN(TRIM(E8))=0,"",VLOOKUP(E8,Sheet2!$B$1:$E$19,2,FALSE)) -> 1073 | L8: =IF(LEN(TRIM(E8))=0,"",VLOOKUP(E8,Sheet2!$B$1:$E$19,3,FALSE)) -> 1108958 | M8: =IF(LEN(TRIM(E8))=0,"",VLOOKUP(E8,Sheet2!$B$1:$E$19,4,FALSE))+(F8-1) -> 3779747
A9: Adler | B9: David | C9: 14-7-1819 | D9: HBMa | E9: 2173 | F9: 207 | G9: 23 | H9: Not available | I9: Not available | J9: =IF(LEN(TRIM(E9))=0,"","http://www.badatelna.eu/reprodukce/?fondId="&K9&"&zaznamId="&L9&"&reproId="&M9) -> http://www.badatelna.eu/reprodukce/?fondId=1073&zaznamId=1108959&reproId=3780200 | K9: =IF(LEN(TRIM(E9))=0,"",VLOOKUP(E9,Sheet2!$B$1:$E$19,2,FALSE)) -> 1073 | L9: =IF(LEN(TRIM(E9))=0,"",VLOOKUP(E9,Sheet2!$B$1:$E$19,3,FALSE)) -> 1108959 | M9: =IF(LEN(TRIM(E9))=0,"",VLOOKUP(E9,Sheet2!$B$1:$E$19,4,FALSE))+(F9-1) -> 3780200
A10: Adler | B10: David | C10: 21-11-1868 | D10: HBMa | E10: 2170 | F10: 29 | G10: 25 | H10: 60 | I10: 56 | J10: =IF(LEN(TRIM(E10))=0,"","http://www.badatelna.eu/reprodukce/?fondId="&K10&"&zaznamId="&L10&"&reproId="&M10) -> http://www.badatelna.eu/reprodukce/?fondId=1073&zaznamId=1108956&reproId=3779621 | K10: =IF(LEN(TRIM(E10))=0,"",VLOOKUP(E10,Sheet2!$B$1:$E$19,2,FALSE)) -> 1073 | L10: =IF(LEN(TRIM(E10))=0,"",VLOOKUP(E10,Sheet2!$B$1:$E$19,3,FALSE)) -> 1108956 | M10: =IF(LEN(TRIM(E10))=0,"",VLOOKUP(E10,Sheet2!$B$1:$E$19,4,FALSE))+(F10-1) -> 3779621
A11: Adler | B11: Elias | C11: 14-7-1851 | D11: HBMa | E11: 2173 | F11: 225 | G11: 55 | H11: Not available | I11: Not available | J11: =IF(LEN(TRIM(E11))=0,"","http://www.badatelna.eu/reprodukce/?fondId="&K11&"&zaznamId="&L11&"&reproId="&M11) -> http://www.badatelna.eu/reprodukce/?fondId=1073&zaznamId=1108959&reproId=3780218 | K11: =IF(LEN(TRIM(E11))=0,"",VLOOKUP(E11,Sheet2!$B$1:$E$19,2,FALSE)) -> 1073 | L11: =IF(LEN(TRIM(E11))=0,"",VLOOKUP(E11,Sheet2!$B$1:$E$19,3,FALSE)) -> 1108959 | M11: =IF(LEN(TRIM(E11))=0,"",VLOOKUP(E11,Sheet2!$B$1:$E$19,4,FALSE))+(F11-1) -> 3780218
A12: Adler | B12: Elias* | C12: 1851 | D12: HBM | E12: 998 | F12: 33 | G12: 31 | H12: 62 | I12: 59 | J12: =IF(LEN(TRIM(E12))=0,"","http://www.badatelna.eu/reprodukce/?fondId="&K12&"&zaznamId="&L12&"&reproId="&M12) -> http://www.badatelna.eu/reprodukce/?fondId=241&zaznamId=1133738&reproId=3885679 | K12: =IF(LEN(TRIM(E12))=0,"",VLOOKUP(E12,Sheet2!$B$1:$E$19,2,FALSE)) -> 241 | L12: =IF(LEN(TRIM(E12))=0,"",VLOOKUP(E12,Sheet2!$B$1:$E$19,3,FALSE)) -> 1133738 | M12: =IF(LEN(TRIM(E12))=0,"",VLOOKUP(E12,Sheet2!$B$1:$E$19,4,FALSE))+(F12-1) -> 3885679
A13: Adler | B13: Elka Willem | C13: 8-11-1872 | D13: HBMa | E13: 2170 | F13: 44 | G13: 40 | H13: 60 | I13: 56 | J13: =IF(LEN(TRIM(E13))=0,"","http://www.badatelna.eu/reprodukce/?fondId="&K13&"&zaznamId="&L13&"&reproId="&M13) -> http://www.badatelna.eu/reprodukce/?fondId=1073&zaznamId=1108956&reproId=3779636 | K13: =IF(LEN(TRIM(E13))=0,"",VLOOKUP(E13,Sheet2!$B$1:$E$19,2,FALSE)) -> 1073 | L13: =IF(LEN(TRIM(E13))=0,"",VLOOKUP(E13,Sheet2!$B$1:$E$19,3,FALSE)) -> 1108956 | M13: =IF(LEN(TRIM(E13))=0,"",VLOOKUP(E13,Sheet2!$B$1:$E$19,4,FALSE))+(F13-1) -> 3779636
A14: Adler | B14: Fanny | C14: 1847 | D14: HBM | E14: 998 | F14: 5 | G14: 3 | H14: 62 | I14: 59 | J14: =IF(LEN(TRIM(E14))=0,"","http://www.badatelna.eu/reprodukce/?fondId="&K14&"&zaznamId="&L14&"&reproId="&M14) -> http://www.badatelna.eu/reprodukce/?fondId=241&zaznamId=1133738&reproId=3885651 | K14: =IF(LEN(TRIM(E14))=0,"",VLOOKUP(E14,Sheet2!$B$1:$E$19,2,FALSE)) -> 241 | L14: =IF(LEN(TRIM(E14))=0,"",VLOOKUP(E14,Sheet2!$B$1:$E$19,3,FALSE)) -> 1133738 | M14: =IF(LEN(TRIM(E14))=0,"",VLOOKUP(E14,Sheet2!$B$1:$E$19,4,FALSE))+(F14-1) -> 3885651
A15: Adler | B15: Golda | C15: 1847 | D15: HBM | E15: 998 | F15: 4 | G15: 2 | H15: 62 | I15: 59 | J15: =IF(LEN(TRIM(E15))=0,"","http://www.badatelna.eu/reprodukce/?fondId="&K15&"&zaznamId="&L15&"&reproId="&M15) -> http://www.badatelna.eu/reprodukce/?fondId=241&zaznamId=1133738&reproId=3885650 | K15: =IF(LEN(TRIM(E15))=0,"",VLOOKUP(E15,Sheet2!$B$1:$E$19,2,FALSE)) -> 241 | L15: =IF(LEN(TRIM(E15))=0,"",VLOOKUP(E15,Sheet2!$B$1:$E$19,3,FALSE)) -> 1133738 | M15: =IF(LEN(TRIM(E15))=0,"",VLOOKUP(E15,Sheet2!$B$1:$E$19,4,FALSE))+(F15-1) -> 3885650
A16: Adler | B16: Isaias | C16: 1863 | D16: HBM | E16: 999 | F16: 83 | G16: 4 | H16: 94 | I16: 152 | J16: =IF(LEN(TRIM(E16))=0,"","http://www.badatelna.eu/reprodukce/?fondId="&K16&"&zaznamId="&L16&"&reproId="&M16) -> http://www.badatelna.eu/reprodukce/?fondId=241&zaznamId=1133739&reproId=3885812 | K16: =IF(LEN(TRIM(E16))=0,"",VLOOKUP(E16,Sheet2!$B$1:$E$19,2,FALSE)) -> 241 | L16: =IF(LEN(TRIM(E16))=0,"",VLOOKUP(E16,Sheet2!$B$1:$E$19,3,FALSE)) -> 1133739 | M16: =IF(LEN(TRIM(E16))=0,"",VLOOKUP(E16,Sheet2!$B$1:$E$19,4,FALSE))+(F16-1) -> 3885812
A17: Adler | B17: Isaias Emanuel | C17: 6-4-1863 | D17: HBMa | E17: 2170 | F17: 7 | G17: 3 | H17: 60 | I17: 56 | J17: =IF(LEN(TRIM(E17))=0,"","http://www.badatelna.eu/reprodukce/?fondId="&K17&"&zaznamId="&L17&"&reproId="&M17) -> http://www.badatelna.eu/reprodukce/?fondId=1073&zaznamId=1108956&reproId=3779599 | K17: =IF(LEN(TRIM(E17))=0,"",VLOOKUP(E17,Sheet2!$B$1:$E$19,2,FALSE)) -> 1073 | L17: =IF(LEN(TRIM(E17))=0,"",VLOOKUP(E17,Sheet2!$B$1:$E$19,3,FALSE)) -> 1108956 | M17: =IF(LEN(TRIM(E17))=0,"",VLOOKUP(E17,Sheet2!$B$1:$E$19,4,FALSE))+(F17-1) -> 3779599
A18: Adler | B18: Johanna | C18: 1854 | D18: HBM | E18: 998 | F18: 41 | G18: 39 | H18: 62 | I18: 59 | J18: =IF(LEN(TRIM(E18))=0,"","http://www.badatelna.eu/reprodukce/?fondId="&K18&"&zaznamId="&L18&"&reproId="&M18) -> http://www.badatelna.eu/reprodukce/?fondId=241&zaznamId=1133738&reproId=3885687 | K18: =IF(LEN(TRIM(E18))=0,"",VLOOKUP(E18,Sheet2!$B$1:$E$19,2,FALSE)) -> 241 | L18: =IF(LEN(TRIM(E18))=0,"",VLOOKUP(E18,Sheet2!$B$1:$E$19,3,FALSE)) -> 1133738 | M18: =IF(LEN(TRIM(E18))=0,"",VLOOKUP(E18,Sheet2!$B$1:$E$19,4,FALSE))+(F18-1) -> 3885687
A19: Adler | B19: Joseph | C19: 8-3-1830 | D19: HBMa | E19: 2173 | F19: 182 | G19: 11 | H19: 184 | I19: 411 | J19: =IF(LEN(TRIM(E19))=0,"","http://www.badatelna.eu/reprodukce/?fondId="&K19&"&zaznamId="&L19&"&reproId="&M19) -> http://www.badatelna.eu/reprodukce/?fondId=1073&zaznamId=1108959&reproId=3780175 | K19: =IF(LEN(TRIM(E19))=0,"",VLOOKUP(E19,Sheet2!$B$1:$E$19,2,FALSE)) -> 1073 | L19: =IF(LEN(TRIM(E19))=0,"",VLOOKUP(E19,Sheet2!$B$1:$E$19,3,FALSE)) -> 1108959 | M19: =IF(LEN(TRIM(E19))=0,"",VLOOKUP(E19,Sheet2!$B$1:$E$19,4,FALSE))+(F19-1) -> 3780175
A20: Adler | B20: Juda | C20: 27-1-1838 | D20: HBMa | E20: 2173 | F20: 221 | G20: 48 | H20: Not available | I20: Not available | J20: =IF(LEN(TRIM(E20))=0,"","http://www.badatelna.eu/reprodukce/?fondId="&K20&"&zaznamId="&L20&"&reproId="&M20) -> http://www.badatelna.eu/reprodukce/?fondId=1073&zaznamId=1108959&reproId=3780214 | K20: =IF(LEN(TRIM(E20))=0,"",VLOOKUP(E20,Sheet2!$B$1:$E$19,2,FALSE)) -> 1073 | L20: =IF(LEN(TRIM(E20))=0,"",VLOOKUP(E20,Sheet2!$B$1:$E$19,3,FALSE)) -> 1108959 | M20: =IF(LEN(TRIM(E20))=0,"",VLOOKUP(E20,Sheet2!$B$1:$E$19,4,FALSE))+(F20-1) -> 3780214
A21: Adler | B21: Julius | C21: 1863 | D21: HBM | E21: 999 | F21: 82 | G21: 3 | H21: 94 | I21: 152 | J21: =IF(LEN(TRIM(E21))=0,"","http://www.badatelna.eu/reprodukce/?fondId="&K21&"&zaznamId="&L21&"&reproId="&M21) -> http://www.badatelna.eu/reprodukce/?fondId=241&zaznamId=1133739&reproId=3885811 | K21: =IF(LEN(TRIM(E21))=0,"",VLOOKUP(E21,Sheet2!$B$1:$E$19,2,FALSE)) -> 241 | L21: =IF(LEN(TRIM(E21))=0,"",VLOOKUP(E21,Sheet2!$B$1:$E$19,3,FALSE)) -> 1133739 | M21: =IF(LEN(TRIM(E21))=0,"",VLOOKUP(E21,Sheet2!$B$1:$E$19,4,FALSE))+(F21-1) -> 3885811
A22: Adler | B22: Julius | C22: 30-12-1934 | D22: HBMa | E22: 2172 | F22: 231 | G22: 211 | H22: Not available | I22: Not available | J22: =IF(LEN(TRIM(E22))=0,"","http://www.badatelna.eu/reprodukce/?fondId="&K22&"&zaznamId="&L22&"&reproId="&M22) -> http://www.badatelna.eu/reprodukce/?fondId=1073&zaznamId=1108958&reproId=3779972 | K22: =IF(LEN(TRIM(E22))=0,"",VLOOKUP(E22,Sheet2!$B$1:$E$19,2,FALSE)) -> 1073 | L22: =IF(LEN(TRIM(E22))=0,"",VLOOKUP(E22,Sheet2!$B$1:$E$19,3,FALSE)) -> 1108958 | M22: =IF(LEN(TRIM(E22))=0,"",VLOOKUP(E22,Sheet2!$B$1:$E$19,4,FALSE))+(F22-1) -> 3779972
A23: Adler | B23: Julius* | C23: 22-2-1863 | D23: HBMa | E23: 2170 | F23: 7 | G23: 3 | H23: 60 | I23: 56 | J23: =IF(LEN(TRIM(E23))=0,"","http://www.badatelna.eu/reprodukce/?fondId="&K23&"&zaznamId="&L23&"&reproId="&M23) -> http://www.badatelna.eu/reprodukce/?fondId=1073&zaznamId=1108956&reproId=3779599 | K23: =IF(LEN(TRIM(E23))=0,"",VLOOKUP(E23,Sheet2!$B$1:$E$19,2,FALSE)) -> 1073 | L23: =IF(LEN(TRIM(E23))=0,"",VLOOKUP(E23,Sheet2!$B$1:$E$19,3,FALSE)) -> 1108956 | M23: =IF(LEN(TRIM(E23))=0,"",VLOOKUP(E23,Sheet2!$B$1:$E$19,4,FALSE))+(F23-1) -> 3779599
A24: Adler | B24: Markus | C24: 1848 | D24: HBM | E24: 998 | F24: 12 | G24: 10 | H24: 62 | I24: 59 | J24: =IF(LEN(TRIM(E24))=0,"","http://www.badatelna.eu/reprodukce/?fondId="&K24&"&zaznamId="&L24&"&reproId="&M24) -> http://www.badatelna.eu/reprodukce/?fondId=241&zaznamId=1133738&reproId=3885658 | K24: =IF(LEN(TRIM(E24))=0,"",VLOOKUP(E24,Sheet2!$B$1:$E$19,2,FALSE)) -> 241 | L24: =IF(LEN(TRIM(E24))=0,"",VLOOKUP(E24,Sheet2!$B$1:$E$19,3,FALSE)) -> 1133738 | M24: =IF(LEN(TRIM(E24))=0,"",VLOOKUP(E24,Sheet2!$B$1:$E$19,4,FALSE))+(F24-1) -> 3885658
A25: Adler | B25: Sallomon | C25: 4-1-1829 | D25: HBMa | E25: 2173 | F25: 181 | G25: 9 | H25: 184 | I25: 411 | J25: =IF(LEN(TRIM(E25))=0,"","http://www.badatelna.eu/reprodukce/?fondId="&K25&"&zaznamId="&L25&"&reproId="&M25) -> http://www.badatelna.eu/reprodukce/?fondId=1073&zaznamId=1108959&reproId=3780174 | K25: =IF(LEN(TRIM(E25))=0,"",VLOOKUP(E25,Sheet2!$B$1:$E$19,2,FALSE)) -> 1073 | L25: =IF(LEN(TRIM(E25))=0,"",VLOOKUP(E25,Sheet2!$B$1:$E$19,3,FALSE)) -> 1108959 | M25: =IF(LEN(TRIM(E25))=0,"",VLOOKUP(E25,Sheet2!$B$1:$E$19,4,FALSE))+(F25-1) -> 3780174
A26: Adler | B26: Sara | C26: 19-1-1831 | D26: HBMa | E26: 2173 | F26: 183 | G26: 13 | H26: 184 | I26: 411 | J26: =IF(LEN(TRIM(E26))=0,"","http://www.badatelna.eu/reprodukce/?fondId="&K26&"&zaznamId="&L26&"&reproId="&M26) -> http://www.badatelna.eu/reprodukce/?fondId=1073&zaznamId=1108959&reproId=3780176 | K26: =IF(LEN(TRIM(E26))=0,"",VLOOKUP(E26,Sheet2!$B$1:$E$19,2,FALSE)) -> 1073 | L26: =IF(LEN(TRIM(E26))=0,"",VLOOKUP(E26,Sheet2!$B$1:$E$19,3,FALSE)) -> 1108959 | M26: =IF(LEN(TRIM(E26))=0,"",VLOOKUP(E26,Sheet2!$B$1:$E$19,4,FALSE))+(F26-1) -> 3780176
A27: Adler | B27: Simon | C27: 13338 | D27: HBMa | E27: 2172 | F27: 237 | G27: 217 | H27: Not available | I27: Not available | J27: =IF(LEN(TRIM(E27))=0,"","http://www.badatelna.eu/reprodukce/?fondId="&K27&"&zaznamId="&L27&"&reproId="&M27) -> http://www.badatelna.eu/reprodukce/?fondId=1073&zaznamId=1108958&reproId=3779978 | K27: =IF(LEN(TRIM(E27))=0,"",VLOOKUP(E27,Sheet2!$B$1:$E$19,2,FALSE)) -> 1073 | L27: =IF(LEN(TRIM(E27))=0,"",VLOOKUP(E27,Sheet2!$B$1:$E$19,3,FALSE)) -> 1108958 | M27: =IF(LEN(TRIM(E27))=0,"",VLOOKUP(E27,Sheet2!$B$1:$E$19,4,FALSE))+(F27-1) -> 3779978
A28: Adlerová | B28: Marianna | C28: 22-8-1929 | D28: HBMa | E28: 2172 | F28: 218 | G28: 202 | H28: Not available | I28: Not available | J28: =IF(LEN(TRIM(E28))=0,"","http://www.badatelna.eu/reprodukce/?fondId="&K28&"&zaznamId="&L28&"&reproId="&M28) -> http://www.badatelna.eu/reprodukce/?fondId=1073&zaznamId=1108958&reproId=3779959 | K28: =IF(LEN(TRIM(E28))=0,"",VLOOKUP(E28,Sheet2!$B$1:$E$19,2,FALSE)) -> 1073 | L28: =IF(LEN(TRIM(E28))=0,"",VLOOKUP(E28,Sheet2!$B$1:$E$19,3,FALSE)) -> 1108958 | M28: =IF(LEN(TRIM(E28))=0,"",VLOOKUP(E28,Sheet2!$B$1:$E$19,4,FALSE))+(F28-1) -> 3779959
A29: Altschul | B29: Julie | C29: 26-8-1917 | D29: HBMa | E29: 2172 | F29: 191 | G29: 181 | H29: Not available | I29: Not available | J29: =IF(LEN(TRIM(E29))=0,"","http://www.badatelna.eu/reprodukce/?fondId="&K29&"&zaznamId="&L29&"&reproId="&M29) -> http://www.badatelna.eu/reprodukce/?fondId=1073&zaznamId=1108958&reproId=3779932 | K29: =IF(LEN(TRIM(E29))=0,"",VLOOKUP(E29,Sheet2!$B$1:$E$19,2,FALSE)) -> 1073 | L29: =IF(LEN(TRIM(E29))=0,"",VLOOKUP(E29,Sheet2!$B$1:$E$19,3,FALSE)) -> 1108958 | M29: =IF(LEN(TRIM(E29))=0,"",VLOOKUP(E29,Sheet2!$B$1:$E$19,4,FALSE))+(F29-1) -> 3779932
A30: Appelfeld | B30: Sonja | C30: 20-20-1894 | D30: HBMa | E30: 2172 | F30: 95 | G30: 94 | H30: 96 | I30: 95 | J30: =IF(LEN(TRIM(E30))=0,"","http://www.badatelna.eu/reprodukce/?fondId="&K30&"&zaznamId="&L30&"&reproId="&M30) -> http://www.badatelna.eu/reprodukce/?fondId=1073&zaznamId=1108958&reproId=3779836 | K30: =IF(LEN(TRIM(E30))=0,"",VLOOKUP(E30,Sheet2!$B$1:$E$19,2,FALSE)) -> 1073 | L30: =IF(LEN(TRIM(E30))=0,"",VLOOKUP(E30,Sheet2!$B$1:$E$19,3,FALSE)) -> 1108958 | M30: =IF(LEN(TRIM(E30))=0,"",VLOOKUP(E30,Sheet2!$B$1:$E$19,4,FALSE))+(F30-1) -> 3779836
A31: Ascher | B31: Jeanette | C31: 20-3-1913 | D31: HBMa | E31: 2172 | F31: 183 | G31: 174 | H31: Not available | I31: Not available | J31: =IF(LEN(TRIM(E31))=0,"","http://www.badatelna.eu/reprodukce/?fondId="&K31&"&zaznamId="&L31&"&reproId="&M31) -> http://www.badatelna.eu/reprodukce/?fondId=1073&zaznamId=1108958&reproId=3779924 | K31: =IF(LEN(TRIM(E31))=0,"",VLOOKUP(E31,Sheet2!$B$1:$E$19,2,FALSE)) -> 1073 | L31: =IF(LEN(TRIM(E31))=0,"",VLOOKUP(E31,Sheet2!$B$1:$E$19,3,FALSE)) -> 1108958 | M31: =IF(LEN(TRIM(E31))=0,"",VLOOKUP(E31,Sheet2!$B$1:$E$19,4,FALSE))+(F31-1) -> 3779924
A32: Austerlitch | B32: Bernard | C32: 11-3-1871 | D32: HBMa | E32: 2170 | F32: 36 | G32: 32 | H32: 60 | I32: 56 | J32: =IF(LEN(TRIM(E32))=0,"","http://www.badatelna.eu/reprodukce/?fondId="&K32&"&zaznamId="&L32&"&reproId="&M32) -> http://www.badatelna.eu/reprodukce/?fondId=1073&zaznamId=1108956&reproId=3779628 | K32: =IF(LEN(TRIM(E32))=0,"",VLOOKUP(E32,Sheet2!$B$1:$E$19,2,FALSE)) -> 1073 | L32: =IF(LEN(TRIM(E32))=0,"",VLOOKUP(E32,Sheet2!$B$1:$E$19,3,FALSE)) -> 1108956 | M32: =IF(LEN(TRIM(E32))=0,"",VLOOKUP(E32,Sheet2!$B$1:$E$19,4,FALSE))+(F32-1) -> 3779628
A33: Austerlitz | B33: Bernath | C33: 15-6-1816 | D33: HBMa | E33: 2173 | F33: 206 | G33: 21 | H33: Not available | I33: Not available | J33: =IF(LEN(TRIM(E33))=0,"","http://www.badatelna.eu/reprodukce/?fondId="&K33&"&zaznamId="&L33&"&reproId="&M33) -> http://www.badatelna.eu/reprodukce/?fondId=1073&zaznamId=1108959&reproId=3780199 | K33: =IF(LEN(TRIM(E33))=0,"",VLOOKUP(E33,Sheet2!$B$1:$E$19,2,FALSE)) -> 1073 | L33: =IF(LEN(TRIM(E33))=0,"",VLOOKUP(E33,Sheet2!$B$1:$E$19,3,FALSE)) -> 1108959 | M33: =IF(LEN(TRIM(E33))=0,"",VLOOKUP(E33,Sheet2!$B$1:$E$19,4,FALSE))+(F33-1) -> 3780199
A34: Austerlitz | B34: David | C34: 19-12-1796 | D34: HBMa | E34: 2173 | F34: 199 | G34: 7 | H34: Not available | I34: Not available | J34: =IF(LEN(TRIM(E34))=0,"","http://www.badatelna.eu/reprodukce/?fondId="&K34&"&zaznamId="&L34&"&reproId="&M34) -> http://www.badatelna.eu/reprodukce/?fondId=1073&zaznamId=1108959&reproId=3780192 | K34: =IF(LEN(TRIM(E34))=0,"",VLOOKUP(E34,Sheet2!$B$1:$E$19,2,FALSE)) -> 1073 | L34: =IF(LEN(TRIM(E34))=0,"",VLOOKUP(E34,Sheet2!$B$1:$E$19,3,FALSE)) -> 1108959 | M34: =IF(LEN(TRIM(E34))=0,"",VLOOKUP(E34,Sheet2!$B$1:$E$19,4,FALSE))+(F34-1) -> 3780192
A35: Austerlitz | B35: Pinchas | C35: 1847 | D35: HBM | E35: 998 | F35: 7 | G35: 5 | H35: 62 | I35: 59 | J35: =IF(LEN(TRIM(E35))=0,"","http://www.badatelna.eu/reprodukce/?fondId="&K35&"&zaznamId="&L35&"&reproId="&M35) -> http://www.badatelna.eu/reprodukce/?fondId=241&zaznamId=1133738&reproId=3885653 | K35: =IF(LEN(TRIM(E35))=0,"",VLOOKUP(E35,Sheet2!$B$1:$E$19,2,FALSE)) -> 241 | L35: =IF(LEN(TRIM(E35))=0,"",VLOOKUP(E35,Sheet2!$B$1:$E$19,3,FALSE)) -> 1133738 | M35: =IF(LEN(TRIM(E35))=0,"",VLOOKUP(E35,Sheet2!$B$1:$E$19,4,FALSE))+(F35-1) -> 3885653
A36: Austerlitz | B36: Sara | C36: 23-9-1828 | D36: HBMa | E36: 2173 | F36: 181 | G36: 9 | H36: 184 | I36: 411 | J36: =IF(LEN(TRIM(E36))=0,"","http://www.badatelna.eu/reprodukce/?fondId="&K36&"&zaznamId="&L36&"&reproId="&M36) -> http://www.badatelna.eu/reprodukce/?fondId=1073&zaznamId=1108959&reproId=3780174 | K36: =IF(LEN(TRIM(E36))=0,"",VLOOKUP(E36,Sheet2!$B$1:$E$19,2,FALSE)) -> 1073 | L36: =IF(LEN(TRIM(E36))=0,"",VLOOKUP(E36,Sheet2!$B$1:$E$19,3,FALSE)) -> 1108959 | M36: =IF(LEN(TRIM(E36))=0,"",VLOOKUP(E36,Sheet2!$B$1:$E$19,4,FALSE))+(F36-1) -> 3780174
A37: B? | B37: Selig | C37: 12-2-1839 | D37: HBMa | E37: 2173 | F37: 221 | G37: 49 | H37: Not available | I37: Not available | J37: =IF(LEN(TRIM(E37))=0,"","http://www.badatelna.eu/reprodukce/?fondId="&K37&"&zaznamId="&L37&"&reproId="&M37) -> http://www.badatelna.eu/reprodukce/?fondId=1073&zaznamId=1108959&reproId=3780214 | K37: =IF(LEN(TRIM(E37))=0,"",VLOOKUP(E37,Sheet2!$B$1:$E$19,2,FALSE)) -> 1073 | L37: =IF(LEN(TRIM(E37))=0,"",VLOOKUP(E37,Sheet2!$B$1:$E$19,3,FALSE)) -> 1108959 | M37: =IF(LEN(TRIM(E37))=0,"",VLOOKUP(E37,Sheet2!$B$1:$E$19,4,FALSE))+(F37-1) -> 3780214
A38: Bacharach | B38: Bernath | C38: 9-3-1803 | D38: HBMa | E38: 2173 | F38: 201 | G38: 12 | H38: Not available | I38: Not available | J38: =IF(LEN(TRIM(E38))=0,"","http://www.badatelna.eu/reprodukce/?fondId="&K38&"&zaznamId="&L38&"&reproId="&M38) -> http://www.badatelna.eu/reprodukce/?fondId=1073&zaznamId=1108959&reproId=3780194 | K38: =IF(LEN(TRIM(E38))=0,"",VLOOKUP(E38,Sheet2!$B$1:$E$19,2,FALSE)) -> 1073 | L38: =IF(LEN(TRIM(E38))=0,"",VLOOKUP(E38,Sheet2!$B$1:$E$19,3,FALSE)) -> 1108959 | M38: =IF(LEN(TRIM(E38))=0,"",VLOOKUP(E38,Sheet2!$B$1:$E$19,4,FALSE))+(F38-1) -> 3780194
A39: Bachrach | B39: Bernath | C39: 24-3-1837 | D39: HBMa | E39: 2173 | F39: 220 | G39: 48 | H39: Not available | I39: Not available | J39: =IF(LEN(TRIM(E39))=0,"","http://www.badatelna.eu/reprodukce/?fondId="&K39&"&zaznamId="&L39&"&reproId="&M39) -> http://www.badatelna.eu/reprodukce/?fondId=1073&zaznamId=1108959&reproId=3780213 | K39: =IF(LEN(TRIM(E39))=0,"",VLOOKUP(E39,Sheet2!$B$1:$E$19,2,FALSE)) -> 1073 | L39: =IF(LEN(TRIM(E39))=0,"",VLOOKUP(E39,Sheet2!$B$1:$E$19,3,FALSE)) -> 1108959 | M39: =IF(LEN(TRIM(E39))=0,"",VLOOKUP(E39,Sheet2!$B$1:$E$19,4,FALSE))+(F39-1) -> 3780213
A40: Bachrach | B40: Bernath Löbl | C40: 22-8-1832 | D40: HBMa | E40: 2173 | F40: 210 | G40: 30 | H40: Not available | I40: Not available | J40: =IF(LEN(TRIM(E40))=0,"","http://www.badatelna.eu/reprodukce/?fondId="&K40&"&zaznamId="&L40&"&reproId="&M40) -> http://www.badatelna.eu/reprodukce/?fondId=1073&zaznamId=1108959&reproId=3780203 | K40: =IF(LEN(TRIM(E40))=0,"",VLOOKUP(E40,Sheet2!$B$1:$E$19,2,FALSE)) -> 1073 | L40: =IF(LEN(TRIM(E40))=0,"",VLOOKUP(E40,Sheet2!$B$1:$E$19,3,FALSE)) -> 1108959 | M40: =IF(LEN(TRIM(E40))=0,"",VLOOKUP(E40,Sheet2!$B$1:$E$19,4,FALSE))+(F40-1) -> 3780203
...

Sheet Sheet2
B1: inv | C1: fond | D1: zaznamid | E1: reproid | F1: page
A2: http://www.badatelna.eu/reprodukce/?fondId=1073&zaznamId=1108960&reproId=3780225 | B2: 995 | C2: 241 | D2: 1133735 | E2: 3885429 | F2: 1
B3: 996 | C3: 241 | D3: 1133736 | E3: 3885569 | F3: 1
B4: 997 | C4: 241 | D4: 1133737 | E4: 3885619 | F4: 1
B5: 998 | C5: 241 | D5: 1133738 | E5: 3885647 | F5: 1
B6: 999 | C6: 241 | D6: 1133739 | E6: 3885730 | F6: 1
B7: 2164 | C7: 1073 | D7: 1108951 | E7: 3778715 | F7: 1
B8: 2165 | C8: 1073 | D8: 1108952 | E8: 3778862 | F8: 1
B9: 2166 | C9: 1073 | D9: 1108953 | E9: 3779225 | F9: 1
B10: 2167 | C10: 1073 | D10: 1108954 | E10: 3779284 | F10: 1
B11: 2168 | C11: 1073 | D11: 1108955 | E11: 3779305 | F11: 1
B12: 2169 | C12: 1073 | D12: 1110078 | E12: 3830578 | F12: 1
B13: 2170 | C13: 1073 | D13: 1108956 | E13: 3779593 | F13: 1
B14: 2171 | C14: 1073 | D14: 1108957 | E14: 3779668 | F14: 1
... B19: 2176 | C19: 1073 | D19: 1108963 | E19: 3780562 | F19: 1
